# Portafolio 001 para tiktok
# Modificado de Ejercicio 032_Casita_DebuggerIntro
from mcpi.minecraft import Minecraft
mc = Minecraft.create()
import time

# Materiales para usar
# A todos se les dio un nombre
# Para no tener que usar solo numeros
cobblestone = 4
oakwoodlog = 17
oakwoodplank = 5
glass = 20
aire = 0
oakwoodstairs = 53
glasspane = 102
torch = 50

# Variable para la velocidad de contrucción
speed = 0.1

# Se obtiene la posicion del jugador
# Se construira relativo a esa posicion. 
x,y,z = mc.player.getTilePos()
x = x+5
z = z-5

time.sleep(3)
##########################################
# Construccion bloque por bloque
# Tenemos que tener y ver un plano 
# con solo la imaginacion es dificil pero posible

# Capa o Nivel 1
mc.setBlock(x+0, y, z, 41)
time.sleep(speed)
mc.setBlock(x+1, y, z, cobblestone)
time.sleep(speed)
mc.setBlock(x+2, y, z, cobblestone)
time.sleep(speed)
mc.setBlock(x+3, y, z, cobblestone)
time.sleep(speed)
mc.setBlock(x+4, y, z, oakwoodlog)
time.sleep(speed)
mc.setBlock(x+0, y, z-1, cobblestone)
time.sleep(speed)
mc.setBlock(x+1, y, z-1, oakwoodplank)
time.sleep(speed)
mc.setBlock(x+2, y, z-1, oakwoodplank)
time.sleep(speed)
mc.setBlock(x+3, y, z-1, oakwoodplank)
time.sleep(speed)
mc.setBlock(x+4, y, z-1, cobblestone)
time.sleep(speed)
mc.setBlock(x+0, y, z-2, cobblestone)
time.sleep(speed)
mc.setBlock(x+1, y, z-2, oakwoodplank)
time.sleep(speed)
mc.setBlock(x+2, y, z-2, oakwoodplank)
time.sleep(speed)
mc.setBlock(x+3, y, z-2, oakwoodplank)
time.sleep(speed)
mc.setBlock(x+4, y, z-2, cobblestone)
time.sleep(speed)
mc.setBlock(x+0, y, z-3, cobblestone)
time.sleep(speed)
mc.setBlock(x+1, y, z-3, oakwoodplank)
time.sleep(speed)
mc.setBlock(x+2, y, z-3, oakwoodplank)
time.sleep(speed)
mc.setBlock(x+3, y, z-3, oakwoodplank)
time.sleep(speed)
mc.setBlock(x+4, y, z-3, cobblestone)
time.sleep(speed)
mc.setBlock(x+0, y, z-4, oakwoodlog)
time.sleep(speed)
mc.setBlock(x+1, y, z-4, cobblestone)
time.sleep(speed)
mc.setBlock(x+2, y, z-4, cobblestone)
time.sleep(speed)
mc.setBlock(x+3, y, z-4, cobblestone)
time.sleep(speed)
mc.setBlock(x+4, y, z-4, oakwoodlog)
time.sleep(speed)



# Breakpoint donde se detendra el debugger
# pdb.set_trace()
# Capa o Nivel 2
mc.setBlock(x+0, y+1, z, oakwoodlog)
time.sleep(speed)
mc.setBlock(x+1, y+1, z, cobblestone)
time.sleep(speed)
mc.setBlock(x+3, y+1, z, cobblestone)
time.sleep(speed)
mc.setBlock(x+4, y+1, z, oakwoodlog)
time.sleep(speed)
mc.setBlock(x+0, y+1, z-1, cobblestone)
time.sleep(speed)
mc.setBlock(x+4, y+1, z-1, cobblestone)
time.sleep(speed)
mc.setBlock(x+0, y+1, z-2, cobblestone)
time.sleep(speed)
mc.setBlock(x+4, y+1, z-2, cobblestone)
time.sleep(speed)
mc.setBlock(x+0, y+1, z-3, cobblestone)
time.sleep(speed)
mc.setBlock(x+4, y+1, z-3, cobblestone)
time.sleep(speed)
mc.setBlock(x+0, y+1, z-4, oakwoodlog)
time.sleep(speed)
mc.setBlock(x+1, y+1, z-4, cobblestone)
time.sleep(speed)
mc.setBlock(x+2, y+1, z-4, cobblestone)
time.sleep(speed)
mc.setBlock(x+3, y+1, z-4, cobblestone)
time.sleep(speed)
mc.setBlock(x+4, y+1, z-4, oakwoodlog)
time.sleep(speed)



# Breakpoint donde se detendra el debugger
# pdb.set_trace()
# Capa o Nivel 3
mc.setBlock(x+0, y+2, z, oakwoodlog)
time.sleep(speed)
mc.setBlock(x+1, y+2, z, cobblestone)
time.sleep(speed)
mc.setBlock(x+3, y+2, z, cobblestone)
time.sleep(speed)
mc.setBlock(x+4, y+2, z, oakwoodlog)
time.sleep(speed)
mc.setBlock(x+0, y+2, z-1, cobblestone)
time.sleep(speed)
mc.setBlock(x+4, y+2, z-1, cobblestone)
time.sleep(speed)
mc.setBlock(x+0, y+2, z-2, glass)
time.sleep(speed)
mc.setBlock(x+4, y+2, z-2, glass)
time.sleep(speed)
mc.setBlock(x+0, y+2, z-3, cobblestone)
time.sleep(speed)
mc.setBlock(x+4, y+2, z-3, cobblestone)
time.sleep(speed)
mc.setBlock(x+0, y+2, z-4, oakwoodlog)
time.sleep(speed)
mc.setBlock(x+1, y+2, z-4, cobblestone)
time.sleep(speed)
mc.setBlock(x+2, y+2, z-4, glass)
time.sleep(speed)
mc.setBlock(x+3, y+2, z-4, cobblestone)
time.sleep(speed)
mc.setBlock(x+4, y+2, z-4, oakwoodlog)
time.sleep(speed)


# Capa o Nivel 4
mc.setBlock(x+0, y+3, z, oakwoodlog)
time.sleep(speed)
mc.setBlock(x+1, y+3, z, cobblestone)
time.sleep(speed)
mc.setBlock(x+2, y+3, z, cobblestone)
time.sleep(speed)
mc.setBlock(x+3, y+3, z, cobblestone)
time.sleep(speed)
mc.setBlock(x+4, y+3, z, oakwoodlog)
time.sleep(speed)
mc.setBlock(x+0, y+3, z-1, cobblestone)
time.sleep(speed)
mc.setBlock(x+4, y+3, z-1, cobblestone)
time.sleep(speed)
mc.setBlock(x+0, y+3, z-2, cobblestone)
time.sleep(speed)
mc.setBlock(x+4, y+3, z-2, cobblestone)
time.sleep(speed)
mc.setBlock(x+0, y+3, z-3, cobblestone)
time.sleep(speed)
mc.setBlock(x+4, y+3, z-3, cobblestone)
time.sleep(speed)
mc.setBlock(x+0, y+3, z-4, oakwoodlog)
time.sleep(speed)
mc.setBlock(x+1, y+3, z-4, cobblestone)
time.sleep(speed)
mc.setBlock(x+2, y+3, z-4, cobblestone)
time.sleep(speed)
mc.setBlock(x+3, y+3, z-4, cobblestone)
time.sleep(speed)
mc.setBlock(x+4, y+3, z-4, oakwoodlog)
time.sleep(speed)

# Capa o Nivel 5
# Stairs para techo
mc.setBlock(x-1, y+4, z+1, oakwoodstairs,3)
time.sleep(speed)
mc.setBlock(x+0, y+4, z+1, oakwoodstairs,3)
time.sleep(speed)
mc.setBlock(x+1, y+4, z+1, oakwoodstairs,3)
time.sleep(speed)
mc.setBlock(x+2, y+4, z+1, oakwoodstairs,3)
time.sleep(speed)
mc.setBlock(x+3, y+4, z+1, oakwoodstairs,3)
time.sleep(speed)
mc.setBlock(x+4, y+4, z+1, oakwoodstairs,3)
time.sleep(speed)
mc.setBlock(x+5, y+4, z+1, oakwoodstairs,3)
time.sleep(speed)

mc.setBlock(x-1, y+4, z-5, oakwoodstairs,2)
time.sleep(speed)
mc.setBlock(x+0, y+4, z-5, oakwoodstairs,2)
time.sleep(speed)
mc.setBlock(x+1, y+4, z-5, oakwoodstairs,2)
time.sleep(speed)
mc.setBlock(x+2, y+4, z-5, oakwoodstairs,2)
time.sleep(speed)
mc.setBlock(x+3, y+4, z-5, oakwoodstairs,2)
time.sleep(speed)
mc.setBlock(x+4, y+4, z-5, oakwoodstairs,2)
time.sleep(speed)
mc.setBlock(x+5, y+4, z-5, oakwoodstairs,2)
time.sleep(speed)
mc.setBlock(x-1, y+4, z-0, oakwoodstairs,0)
time.sleep(speed)
mc.setBlock(x-1, y+4, z-1, oakwoodstairs,0)
time.sleep(speed)
mc.setBlock(x-1, y+4, z-2, oakwoodstairs,0)
time.sleep(speed)
mc.setBlock(x-1, y+4, z-3, oakwoodstairs,0)
time.sleep(speed)
mc.setBlock(x-1, y+4, z-4, oakwoodstairs,0)
time.sleep(speed)
mc.setBlock(x+5, y+4, z-0, oakwoodstairs,1)
time.sleep(speed)
mc.setBlock(x+5, y+4, z-1, oakwoodstairs,1)
time.sleep(speed)
mc.setBlock(x+5, y+4, z-2, oakwoodstairs,1)
time.sleep(speed)
mc.setBlock(x+5, y+4, z-3, oakwoodstairs,1)
time.sleep(speed)
mc.setBlock(x+5, y+4, z-4, oakwoodstairs,1)
time.sleep(speed)

# Planks
mc.setBlock(x+0, y+4, z, oakwoodplank)
time.sleep(speed)
mc.setBlock(x+1, y+4, z, oakwoodplank)
time.sleep(speed)
mc.setBlock(x+2, y+4, z, oakwoodplank)
time.sleep(speed)
mc.setBlock(x+3, y+4, z, oakwoodplank)
time.sleep(speed)
mc.setBlock(x+4, y+4, z, oakwoodplank)
time.sleep(speed)
mc.setBlock(x+0, y+4, z-1, oakwoodplank)
time.sleep(speed)
mc.setBlock(x+4, y+4, z-1, oakwoodplank)
time.sleep(speed)
mc.setBlock(x+0, y+4, z-2, oakwoodplank)
time.sleep(speed)
mc.setBlock(x+4, y+4, z-2, oakwoodplank)
time.sleep(speed)
mc.setBlock(x+0, y+4, z-3, oakwoodplank)
time.sleep(speed)
mc.setBlock(x+4, y+4, z-3, oakwoodplank)
time.sleep(speed)
mc.setBlock(x+0, y+4, z-4, oakwoodplank)
time.sleep(speed)
mc.setBlock(x+1, y+4, z-4, oakwoodplank)
time.sleep(speed)
mc.setBlock(x+2, y+4, z-4, oakwoodplank)
time.sleep(speed)
mc.setBlock(x+3, y+4, z-4, oakwoodplank)
time.sleep(speed)
mc.setBlock(x+4, y+4, z-4, oakwoodplank)
time.sleep(speed)

# Capa o Nivel 6
# Stairs
mc.setBlock(x+0, y+5, z, oakwoodstairs,3)
time.sleep(speed)
mc.setBlock(x+1, y+5, z, oakwoodstairs,3)
time.sleep(speed)
mc.setBlock(x+2, y+5, z, oakwoodstairs,3)
time.sleep(speed)
mc.setBlock(x+3, y+5, z, oakwoodstairs,3)
time.sleep(speed)
mc.setBlock(x+4, y+5, z, oakwoodstairs,3)
time.sleep(speed)
mc.setBlock(x+0, y+5, z-1, oakwoodstairs,0)
time.sleep(speed)
mc.setBlock(x+0, y+5, z-2, oakwoodstairs,0)
time.sleep(speed)
mc.setBlock(x+0, y+5, z-3, oakwoodstairs,0)
time.sleep(speed)
mc.setBlock(x+0, y+5, z-4, oakwoodstairs,0)
time.sleep(speed)
mc.setBlock(x+4, y+5, z-1, oakwoodstairs,1)
time.sleep(speed)
mc.setBlock(x+4, y+5, z-2, oakwoodstairs,1)
time.sleep(speed)
mc.setBlock(x+4, y+5, z-3, oakwoodstairs,1)
time.sleep(speed)
mc.setBlock(x+4, y+5, z-4, oakwoodstairs,1)
time.sleep(speed)
mc.setBlock(x+1, y+5, z-4, oakwoodstairs,2)
time.sleep(speed)
mc.setBlock(x+2, y+5, z-4, oakwoodstairs,2)
time.sleep(speed)
mc.setBlock(x+3, y+5, z-4, oakwoodstairs,2)
time.sleep(speed)
# Planks
mc.setBlock(x+1, y+5, z-1, oakwoodplank)
time.sleep(speed)
mc.setBlock(x+2, y+5, z-1, oakwoodplank)
time.sleep(speed)
mc.setBlock(x+3, y+5, z-1, oakwoodplank)
time.sleep(speed)
mc.setBlock(x+1, y+5, z-2, oakwoodplank)
time.sleep(speed)
mc.setBlock(x+3, y+5, z-2, oakwoodplank)
time.sleep(speed)
mc.setBlock(x+1, y+5, z-3, oakwoodplank)
time.sleep(speed)
mc.setBlock(x+2, y+5, z-3, oakwoodplank)
time.sleep(speed)
mc.setBlock(x+3, y+5, z-3, oakwoodplank)
time.sleep(speed)



# Capa o Nivel 7
# Stairs
mc.setBlock(x+1, y+6, z-1, oakwoodstairs,3)
time.sleep(speed)
mc.setBlock(x+2, y+6, z-1, oakwoodstairs,3)
time.sleep(speed)
mc.setBlock(x+3, y+6, z-1, oakwoodstairs,3)
time.sleep(speed)
mc.setBlock(x+1, y+6, z-3, oakwoodstairs,2)
time.sleep(speed)
mc.setBlock(x+2, y+6, z-3, oakwoodstairs,2)
time.sleep(speed)
mc.setBlock(x+3, y+6, z-3, oakwoodstairs,2)
time.sleep(speed)
mc.setBlock(x+1, y+6, z-2, oakwoodstairs,0)
time.sleep(speed)
mc.setBlock(x+3, y+6, z-2, oakwoodstairs,1)
time.sleep(speed)
# Plank
mc.setBlock(x+2, y+6, z-2, oakwoodplank)
time.sleep(speed)


# Detalles
# Puerta, cama, antorchas
# Escaleras en frente de la puerta
mc.setBlock(x+2, y, z+1, oakwoodstairs,3)
time.sleep(speed)
# Puerta
mc.setBlock(x+2, y+2, z, 64,11)
time.sleep(speed)
mc.setBlock(x+2, y+1, z, 64,3)
time.sleep(speed)
# Cama
mc.setBlock(x+1, y+1, z-3, 26,10)
time.sleep(speed)
mc.setBlock(x+1, y+1, z-2, 26,2)
time.sleep(speed)
# Silla
mc.setBlock(x+3, y+1, z-3, oakwoodstairs,3)
time.sleep(speed)
# Antorchas
mc.setBlock(x+1, y+3, z+1, torch,3)
time.sleep(speed)
mc.setBlock(x+3, y+3, z+1, torch,3)
time.sleep(speed)
mc.setBlock(x+2, y+3, z-3, torch,3)
time.sleep(10)


# Al final borramos la casita
mc.setBlocks(x-1, y, z+1, x+5, y+6, z-5, 0)
